
<?xml version='1.0' encoding='utf-8'?>
<robot name="partnet_79d44361e37844bb80f590c116e61d4c">
    <link name="base"><inertial><mass value="1.0" /><inertia ixx="1.0" ixy="0.0" ixz="0.0" iyy="1.0" iyz="0.0" izz="1.0" /></inertial></link>

    <material name="mat_1">
        <color rgba="0.6972621022775551 0.840118525694941 0.08965314132943414 1"/>
    </material>

    <material name="mat_2">
        <color rgba="0.5299076420511931 0.9991252662921831 0.4624387957458189 1"/>
    </material>

    <material name="mat_3">
        <color rgba="0.8178696641895816 0.05558673744992704 0.5379184656743201 1"/>
    </material>

    <link name="link_0">
    <inertial>
        <origin rpy="0 0 0" xyz="0 0 0"/>
        <mass value="0.75"/>
        <inertia ixx="8.430386777381608e-05" ixy="1.4834058775849982e-10" ixz="1.0169114738173443e-07" iyy="8.174002269698219e-05" iyz="-6.541002154189298e-08" izz="8.25774674376256e-06"/>
    </inertial>
    <visual>
        <origin rpy="0 0 0" xyz="0 0 0"/>
        <geometry>
        <mesh filename="./meshes/pyramid_7.obj" scale="1 1 1"/>
        </geometry>
        <material name="mat_3"/>
    </visual>
    <collision>
        <origin rpy="0 0 0" xyz="0 0 0"/>
        <geometry>
        <mesh filename="./meshes/pyramid_7.obj" scale="1 1 1"/>
        </geometry>
    </collision>
    </link>

    <joint name="joint_0" type="revolute" >
        <origin xyz="0 0 0.7048908018240785" />
        <axis xyz="0 1 0" />
        <child link="link_1" />
        <parent link="link_0" />
        <limit lower="-1.57079632679" upper="1.57079632679" effort="10" velocity="3"/>
    </joint>

    <link name="link_1">
    <inertial>
        <origin rpy="0 0 0" xyz="0 0 0"/>
        <mass value="0.75"/>
        <inertia ixx="0.00043836291717043474" ixy="5.032789161939161e-12" ixz="-7.168615266132109e-11" iyy="0.00047252406008932934" iyz="4.994920592846701e-15" izz="6.036191546709928e-05"/>
    </inertial>
    <visual>
        <origin rpy="0 0 0" xyz="0 0 0"/>
        <geometry>
        <mesh filename="./meshes/cube_9.obj" scale="1 1 1"/>
        </geometry>
        <material name="mat_3"/>
    </visual>
    <collision>
        <origin rpy="0 0 0" xyz="0 0 0"/>
        <geometry>
        <mesh filename="./meshes/cube_9.obj" scale="1 1 1"/>
        </geometry>
    </collision>
    </link>

    <joint name="joint_1" type="revolute" >
        <origin xyz="0 0 0.6139314876730542" />
        <axis xyz="0 1 0" />
        <child link="link_2" />
        <parent link="link_1" />
        <limit lower="-1.57079632679" upper="1.57079632679" effort="10" velocity="3"/>
    </joint>

    <link name="link_2">
    <inertial>
        <origin rpy="0 0 0" xyz="0 0 0"/>
        <mass value="0.75"/>
        <inertia ixx="9.831554238947808e-06" ixy="-3.4271774981904217e-13" ixz="4.535777571501828e-13" iyy="9.072599929094288e-06" iyz="8.181874256477793e-13" izz="1.5314553358607485e-06"/>
    </inertial>
    <visual>
        <origin rpy="0 0 0" xyz="0 0 0"/>
        <geometry>
        <mesh filename="./meshes/diamond_9.obj" scale="1 1 1"/>
        </geometry>
        <material name="mat_1"/>
    </visual>
    <collision>
        <origin rpy="0 0 0" xyz="0 0 0"/>
        <geometry>
        <mesh filename="./meshes/diamond_9.obj" scale="1 1 1"/>
        </geometry>
    </collision>
    </link>

    <joint name="joint_base" type="fixed">
        <origin rpy="1.570796326794897 0 -1.570796326794897" xyz="1.5 0 0" />
        <child link="link_0" />
        <parent link="base" />
    </joint>
</robot>