
<?xml version='1.0' encoding='utf-8'?>
<robot name="partnet_8cf29286a6ba449e9b1eff88cc29fce6">
    <link name="base"><inertial><mass value="1.0" /><inertia ixx="1.0" ixy="0.0" ixz="0.0" iyy="1.0" iyz="0.0" izz="1.0" /></inertial></link>

    <material name="mat_1">
        <color rgba="0.0780924378627248 0.29134830764196906 0.5275401640563341 1"/>
    </material>

    <material name="mat_2">
        <color rgba="0.7965018710824409 0.7570107871471645 0.6380610640750937 1"/>
    </material>

    <material name="mat_3">
        <color rgba="0.4229020776539478 0.7507974502192228 0.15327735561509537 1"/>
    </material>

    <link name="link_0">
    <inertial>
        <origin rpy="0 0 0" xyz="0 0 0"/>
        <mass value="0.75"/>
        <inertia ixx="0.0018010362233489693" ixy="2.288897148838566e-11" ixz="6.472439952280834e-12" iyy="0.001822506537748781" iyz="-7.284665873168603e-11" izz="0.00023269553888183233"/>
    </inertial>
    <visual>
        <origin rpy="0 0 0" xyz="0 0 0"/>
        <geometry>
        <mesh filename="./meshes/cylinder_9.obj" scale="1 1 1"/>
        </geometry>
        <material name="mat_1"/>
    </visual>
    <collision>
        <origin rpy="0 0 0" xyz="0 0 0"/>
        <geometry>
        <mesh filename="./meshes/cylinder_9.obj" scale="1 1 1"/>
        </geometry>
    </collision>
    </link>

    <joint name="joint_0" type="revolute" >
        <origin xyz="0 0 0.777610732795571" />
        <axis xyz="0 1 0" />
        <child link="link_1" />
        <parent link="link_0" />
        <limit lower="-1.57079632679" upper="1.57079632679" effort="10" velocity="3"/>
    </joint>

    <link name="link_1">
    <inertial>
        <origin rpy="0 0 0" xyz="0 0 0"/>
        <mass value="0.75"/>
        <inertia ixx="5.752046192924936e-05" ixy="-1.4533765668832461e-09" ixz="2.185475125985282e-08" iyy="5.8734931386289976e-05" iyz="5.67680066037933e-09" izz="1.2078300204579844e-05"/>
    </inertial>
    <visual>
        <origin rpy="0 0 0" xyz="0 0 0"/>
        <geometry>
        <mesh filename="./meshes/tetrahedron_2.obj" scale="1 1 1"/>
        </geometry>
        <material name="mat_1"/>
    </visual>
    <collision>
        <origin rpy="0 0 0" xyz="0 0 0"/>
        <geometry>
        <mesh filename="./meshes/tetrahedron_2.obj" scale="1 1 1"/>
        </geometry>
    </collision>
    </link>

    <joint name="joint_1" type="revolute" >
        <origin xyz="0 0 0.5655574742598284" />
        <axis xyz="0 1 0" />
        <child link="link_2" />
        <parent link="link_1" />
        <limit lower="-1.57079632679" upper="1.57079632679" effort="10" velocity="3"/>
    </joint>

    <link name="link_2">
    <inertial>
        <origin rpy="0 0 0" xyz="0 0 0"/>
        <mass value="0.75"/>
        <inertia ixx="1.1584365781263012e-05" ixy="-4.5705062960827017e-10" ixz="6.76752757776784e-09" iyy="1.363271323262292e-05" iyz="1.1579298532759794e-09" izz="4.30020315678666e-06"/>
    </inertial>
    <visual>
        <origin rpy="0 0 0" xyz="0 0 0"/>
        <geometry>
        <mesh filename="./meshes/tetrahedron_5.obj" scale="1 1 1"/>
        </geometry>
        <material name="mat_2"/>
    </visual>
    <collision>
        <origin rpy="0 0 0" xyz="0 0 0"/>
        <geometry>
        <mesh filename="./meshes/tetrahedron_5.obj" scale="1 1 1"/>
        </geometry>
    </collision>
    </link>

    <joint name="joint_base" type="fixed">
        <origin rpy="1.570796326794897 0 -1.570796326794897" xyz="1.5 0 0" />
        <child link="link_0" />
        <parent link="base" />
    </joint>
</robot>