
<?xml version='1.0' encoding='utf-8'?>
<robot name="partnet_0c557f39ca694843b256d92a48b988f0">
    <link name="base"><inertial><mass value="1.0" /><inertia ixx="1.0" ixy="0.0" ixz="0.0" iyy="1.0" iyz="0.0" izz="1.0" /></inertial></link>

    <material name="mat_1">
        <color rgba="0.40454561145080503 0.8918677454262821 0.6004473302903736 1"/>
    </material>

    <material name="mat_2">
        <color rgba="0.839679754034989 0.9445346657810606 0.7498901233322489 1"/>
    </material>

    <material name="mat_3">
        <color rgba="0.05523691357774507 0.8956839514665432 0.8718086361639633 1"/>
    </material>

    <link name="link_0">
    <inertial>
        <origin rpy="0 0 0" xyz="0 0 0"/>
        <mass value="0.75"/>
        <inertia ixx="0.00010072119405053526" ixy="1.1317854720262734e-12" ixz="1.0815684553550996e-13" iyy="0.0001002644363689956" iyz="-4.153420276608117e-12" izz="1.2106943273364481e-05"/>
    </inertial>
    <visual>
        <origin rpy="0 0 0" xyz="0 0 0"/>
        <geometry>
        <mesh filename="./meshes/cylinder_7.obj" scale="1 1 1"/>
        </geometry>
        <material name="mat_1"/>
    </visual>
    <collision>
        <origin rpy="0 0 0" xyz="0 0 0"/>
        <geometry>
        <mesh filename="./meshes/cylinder_7.obj" scale="1 1 1"/>
        </geometry>
    </collision>
    </link>

    <joint name="joint_0" type="revolute" >
        <origin xyz="0 0 0.44213346776472306" />
        <axis xyz="0 1 0" />
        <child link="link_1" />
        <parent link="link_0" />
        <limit lower="-1.57079632679" upper="1.57079632679" effort="10" velocity="3"/>
    </joint>

    <link name="link_1">
    <inertial>
        <origin rpy="0 0 0" xyz="0 0 0"/>
        <mass value="0.75"/>
        <inertia ixx="0.00017284402692744445" ixy="-2.6751154495996267e-11" ixz="2.7453820350537026e-09" iyy="0.00018896181321961315" iyz="-1.4760357127375947e-10" izz="1.8066711772234854e-05"/>
    </inertial>
    <visual>
        <origin rpy="0 0 0" xyz="0 0 0"/>
        <geometry>
        <mesh filename="./meshes/torus_3.obj" scale="1 1 1"/>
        </geometry>
        <material name="mat_3"/>
    </visual>
    <collision>
        <origin rpy="0 0 0" xyz="0 0 0"/>
        <geometry>
        <mesh filename="./meshes/torus_3.obj" scale="1 1 1"/>
        </geometry>
    </collision>
    </link>

    <joint name="joint_1" type="revolute" >
        <origin xyz="0 0 0.7309651474987334" />
        <axis xyz="0 1 0" />
        <child link="link_2" />
        <parent link="link_1" />
        <limit lower="-1.57079632679" upper="1.57079632679" effort="10" velocity="3"/>
    </joint>

    <link name="link_2">
    <inertial>
        <origin rpy="0 0 0" xyz="0 0 0"/>
        <mass value="0.75"/>
        <inertia ixx="0.0002190254509030383" ixy="-1.5995367077592857e-11" ixz="2.2524790159321923e-09" iyy="0.00022741744116478238" iyz="-1.3740421731493796e-10" izz="9.724466888361538e-06"/>
    </inertial>
    <visual>
        <origin rpy="0 0 0" xyz="0 0 0"/>
        <geometry>
        <mesh filename="./meshes/torus_6.obj" scale="1 1 1"/>
        </geometry>
        <material name="mat_1"/>
    </visual>
    <collision>
        <origin rpy="0 0 0" xyz="0 0 0"/>
        <geometry>
        <mesh filename="./meshes/torus_6.obj" scale="1 1 1"/>
        </geometry>
    </collision>
    </link>

    <joint name="joint_base" type="fixed">
        <origin rpy="1.570796326794897 0 -1.570796326794897" xyz="1.5 0 0" />
        <child link="link_0" />
        <parent link="base" />
    </joint>
</robot>