
<?xml version='1.0' encoding='utf-8'?>
<robot name="partnet_4a41c0077d1649168bc5ed1550e41d0f">
    <link name="base"><inertial><mass value="1.0" /><inertia ixx="1.0" ixy="0.0" ixz="0.0" iyy="1.0" iyz="0.0" izz="1.0" /></inertial></link>

    <material name="mat_1">
        <color rgba="0.3105698122795638 0.9352891850072557 0.11745066445418251 1"/>
    </material>

    <material name="mat_2">
        <color rgba="0.045143952579145274 0.1540520004661794 0.5369602021331826 1"/>
    </material>

    <material name="mat_3">
        <color rgba="0.8877433050336665 0.7069391879363792 0.08798924012612608 1"/>
    </material>

    <link name="link_0">
    <inertial>
        <origin rpy="0 0 0" xyz="0 0 0"/>
        <mass value="0.75"/>
        <inertia ixx="0.00028198614809330945" ixy="1.5291763048385704e-07" ixz="5.75013770144003e-08" iyy="0.0003182551393233221" iyz="-3.6939891121459006e-07" izz="5.4420876598236427e-05"/>
    </inertial>
    <visual>
        <origin rpy="0 0 0" xyz="0 0 0"/>
        <geometry>
        <mesh filename="./meshes/001_9.obj" scale="1 1 1"/>
        </geometry>
        <material name="mat_1"/>
    </visual>
    <collision>
        <origin rpy="0 0 0" xyz="0 0 0"/>
        <geometry>
        <mesh filename="./meshes/001_9.obj" scale="1 1 1"/>
        </geometry>
    </collision>
    </link>

    <joint name="joint_0" type="revolute" >
        <origin xyz="0 0 0.7" />
        <axis xyz="0 1 0" />
        <child link="link_1" />
        <parent link="link_0" />
        <limit lower="-0.872665" upper="0.872665" effort="10" velocity="3"/>
    </joint>

    <link name="link_1">
    <inertial>
        <origin rpy="0 0 0" xyz="0 0 0"/>
        <mass value="0.75"/>
        <inertia ixx="0.00028198614809330945" ixy="1.5291763048385704e-07" ixz="5.75013770144003e-08" iyy="0.0003182551393233221" iyz="-3.6939891121459006e-07" izz="5.4420876598236427e-05"/>
    </inertial>
    <visual>
        <origin rpy="0 0 0" xyz="0 0 0"/>
        <geometry>
        <mesh filename="./meshes/001_9.obj" scale="1 1 1"/>
        </geometry>
        <material name="mat_2"/>
    </visual>
    <collision>
        <origin rpy="0 0 0" xyz="0 0 0"/>
        <geometry>
        <mesh filename="./meshes/001_9.obj" scale="1 1 1"/>
        </geometry>
    </collision>
    </link>

    <joint name="joint_1" type="revolute" >
        <origin xyz="0 0 0.7" />
        <axis xyz="0 1 0" />
        <child link="link_2" />
        <parent link="link_1" />
        <limit lower="-0.872665" upper="0.872665" effort="10" velocity="3"/>
    </joint>

    <link name="link_2">
    <inertial>
        <origin rpy="0 0 0" xyz="0 0 0"/>
        <mass value="0.75"/>
        <inertia ixx="0.0006970302431369849" ixy="2.765067714180376e-07" ixz="4.3475500861886356e-07" iyy="0.0006177461486070379" iyz="-8.871647443520344e-05" izz="0.00024791834619423985"/>
    </inertial>
    <visual>
        <origin rpy="0 0 0" xyz="0 0 0"/>
        <geometry>
        <mesh filename="./meshes/000_7.obj" scale="1 1 1"/>
        </geometry>
        <material name="mat_3"/>
    </visual>
    <collision>
        <origin rpy="0 0 0" xyz="0 0 0"/>
        <geometry>
        <mesh filename="./meshes/000_7.obj" scale="1 1 1"/>
        </geometry>
    </collision>
    </link>

    <joint name="joint_base" type="fixed">
        <origin rpy="1.570796326794897 0 -1.570796326794897" xyz="1.05 0 0" />
        <child link="link_0" />
        <parent link="base" />
    </joint>
</robot>