
<?xml version='1.0' encoding='utf-8'?>
<robot name="partnet_5c50097ab199472ca03de283655e099b">
    <link name="base"><inertial><mass value="1.0" /><inertia ixx="1.0" ixy="0.0" ixz="0.0" iyy="1.0" iyz="0.0" izz="1.0" /></inertial></link>

    <material name="mat_1">
        <color rgba="0.908356233764159 0.5707943007603787 0.7350267623004232 1"/>
    </material>

    <material name="mat_2">
        <color rgba="0.2671697420587642 0.39144834090095293 0.6621562017629452 1"/>
    </material>

    <material name="mat_3">
        <color rgba="0.62287556612774 0.7132286324105328 0.32510825221381856 1"/>
    </material>

    <link name="link_0">
    <inertial>
        <origin rpy="0 0 0" xyz="0 0 0"/>
        <mass value="0.75"/>
        <inertia ixx="0.0006970302431369849" ixy="2.765067714180376e-07" ixz="4.3475500861886356e-07" iyy="0.0006177461486070379" iyz="-8.871647443520344e-05" izz="0.00024791834619423985"/>
    </inertial>
    <visual>
        <origin rpy="0 0 0" xyz="0 0 0"/>
        <geometry>
        <mesh filename="./meshes/000_5.obj" scale="1 1 1"/>
        </geometry>
        <material name="mat_1"/>
    </visual>
    <collision>
        <origin rpy="0 0 0" xyz="0 0 0"/>
        <geometry>
        <mesh filename="./meshes/000_5.obj" scale="1 1 1"/>
        </geometry>
    </collision>
    </link>

    <joint name="joint_0" type="revolute" >
        <origin xyz="0 0 0.7" />
        <axis xyz="0 1 0" />
        <child link="link_1" />
        <parent link="link_0" />
        <limit lower="-0.872665" upper="0.872665" effort="10" velocity="3"/>
    </joint>

    <link name="link_1">
    <inertial>
        <origin rpy="0 0 0" xyz="0 0 0"/>
        <mass value="0.75"/>
        <inertia ixx="0.0004397613408125844" ixy="9.9295017092963e-08" ixz="-3.7141032753046395e-08" iyy="0.00044833212641787776" iyz="-1.206611973426756e-06" izz="7.890678398180441e-05"/>
    </inertial>
    <visual>
        <origin rpy="0 0 0" xyz="0 0 0"/>
        <geometry>
        <mesh filename="./meshes/003_5.obj" scale="1 1 1"/>
        </geometry>
        <material name="mat_2"/>
    </visual>
    <collision>
        <origin rpy="0 0 0" xyz="0 0 0"/>
        <geometry>
        <mesh filename="./meshes/003_5.obj" scale="1 1 1"/>
        </geometry>
    </collision>
    </link>

    <joint name="joint_1" type="revolute" >
        <origin xyz="0 0 0.7" />
        <axis xyz="0 1 0" />
        <child link="link_2" />
        <parent link="link_1" />
        <limit lower="-0.872665" upper="0.872665" effort="10" velocity="3"/>
    </joint>

    <link name="link_2">
    <inertial>
        <origin rpy="0 0 0" xyz="0 0 0"/>
        <mass value="0.75"/>
        <inertia ixx="0.0005327014250829038" ixy="-8.910208422563106e-08" ixz="9.910415466524238e-09" iyy="0.0005015348207404789" iyz="1.228752069510437e-08" izz="0.0001362037121752979"/>
    </inertial>
    <visual>
        <origin rpy="0 0 0" xyz="0 0 0"/>
        <geometry>
        <mesh filename="./meshes/002_2.obj" scale="1 1 1"/>
        </geometry>
        <material name="mat_3"/>
    </visual>
    <collision>
        <origin rpy="0 0 0" xyz="0 0 0"/>
        <geometry>
        <mesh filename="./meshes/002_2.obj" scale="1 1 1"/>
        </geometry>
    </collision>
    </link>

    <joint name="joint_base" type="fixed">
        <origin rpy="1.570796326794897 0 -1.570796326794897" xyz="1.05 0 0" />
        <child link="link_0" />
        <parent link="base" />
    </joint>
</robot>