
<?xml version='1.0' encoding='utf-8'?>
<robot name="partnet_1732c20d57d542cabf89fddcb2687bd2">
    <link name="base"><inertial><mass value="1.0" /><inertia ixx="1.0" ixy="0.0" ixz="0.0" iyy="1.0" iyz="0.0" izz="1.0" /></inertial></link>

    <material name="mat_1">
        <color rgba="0.786526228016608 0.8349516029882103 0.7946381344041736 1"/>
    </material>

    <material name="mat_2">
        <color rgba="0.7899965018209403 0.8973314398122577 0.5350857709235853 1"/>
    </material>

    <material name="mat_3">
        <color rgba="0.28458690163900136 0.05035196446143331 0.6518274647342317 1"/>
    </material>

    <link name="link_0">
    <inertial>
        <origin rpy="0 0 0" xyz="0 0 0"/>
        <mass value="0.75"/>
        <inertia ixx="5.7810787666132016e-05" ixy="2.5566643041569447e-12" ixz="-2.141029994627062e-22" iyy="6.396990089346355e-05" iyz="-3.645400449987523e-21" izz="1.9821919008883163e-05"/>
    </inertial>
    <visual>
        <origin rpy="0 0 0" xyz="0 0 0"/>
        <geometry>
        <mesh filename="./meshes/sphere_7.obj" scale="1 1 1"/>
        </geometry>
        <material name="mat_1"/>
    </visual>
    <collision>
        <origin rpy="0 0 0" xyz="0 0 0"/>
        <geometry>
        <mesh filename="./meshes/sphere_7.obj" scale="1 1 1"/>
        </geometry>
    </collision>
    </link>

    <joint name="joint_0" type="revolute" >
        <origin xyz="0 0 0.4069421926094756" />
        <axis xyz="0 1 0" />
        <child link="link_1" />
        <parent link="link_0" />
        <limit lower="-1.57079632679" upper="1.57079632679" effort="10" velocity="3"/>
    </joint>

    <link name="link_1">
    <inertial>
        <origin rpy="0 0 0" xyz="0 0 0"/>
        <mass value="0.75"/>
        <inertia ixx="0.0018264590054730264" ixy="1.3291784227798729e-11" ixz="-1.759804337567799e-10" iyy="0.0018337888240940277" iyz="2.2035758418311753e-14" izz="0.0001330898710934881"/>
    </inertial>
    <visual>
        <origin rpy="0 0 0" xyz="0 0 0"/>
        <geometry>
        <mesh filename="./meshes/cube_3.obj" scale="1 1 1"/>
        </geometry>
        <material name="mat_3"/>
    </visual>
    <collision>
        <origin rpy="0 0 0" xyz="0 0 0"/>
        <geometry>
        <mesh filename="./meshes/cube_3.obj" scale="1 1 1"/>
        </geometry>
    </collision>
    </link>

    <joint name="joint_1" type="revolute" >
        <origin xyz="0 0 0.8910521918122716" />
        <axis xyz="0 1 0" />
        <child link="link_2" />
        <parent link="link_1" />
        <limit lower="-1.57079632679" upper="1.57079632679" effort="10" velocity="3"/>
    </joint>

    <link name="link_2">
    <inertial>
        <origin rpy="0 0 0" xyz="0 0 0"/>
        <mass value="0.75"/>
        <inertia ixx="0.00012259464257801455" ixy="-2.0998443054969493e-12" ixz="-6.419868113808246e-12" iyy="0.0001296834306634492" iyz="2.614571417162111e-12" izz="6.1023137982808734e-05"/>
    </inertial>
    <visual>
        <origin rpy="0 0 0" xyz="0 0 0"/>
        <geometry>
        <mesh filename="./meshes/cone_7.obj" scale="1 1 1"/>
        </geometry>
        <material name="mat_1"/>
    </visual>
    <collision>
        <origin rpy="0 0 0" xyz="0 0 0"/>
        <geometry>
        <mesh filename="./meshes/cone_7.obj" scale="1 1 1"/>
        </geometry>
    </collision>
    </link>

    <joint name="joint_base" type="fixed">
        <origin rpy="1.570796326794897 0 -1.570796326794897" xyz="1.5 0 0" />
        <child link="link_0" />
        <parent link="base" />
    </joint>
</robot>