
<?xml version='1.0' encoding='utf-8'?>
<robot name="partnet_33d8a3c32a7d46aab7d3f915928274e3">
    <link name="base"><inertial><mass value="1.0" /><inertia ixx="1.0" ixy="0.0" ixz="0.0" iyy="1.0" iyz="0.0" izz="1.0" /></inertial></link>

    <material name="mat_1">
        <color rgba="0.05551017630159982 0.4016517197344488 0.206092056435059 1"/>
    </material>

    <material name="mat_2">
        <color rgba="0.48555185156547265 0.027754322151921085 0.062206048374970346 1"/>
    </material>

    <material name="mat_3">
        <color rgba="0.3853914908299493 0.3452154121760722 0.1948234977490253 1"/>
    </material>

    <link name="link_0">
    <inertial>
        <origin rpy="0 0 0" xyz="0 0 0"/>
        <mass value="0.75"/>
        <inertia ixx="0.00028198614809330945" ixy="1.5291763048385704e-07" ixz="5.75013770144003e-08" iyy="0.0003182551393233221" iyz="-3.6939891121459006e-07" izz="5.4420876598236427e-05"/>
    </inertial>
    <visual>
        <origin rpy="0 0 0" xyz="0 0 0"/>
        <geometry>
        <mesh filename="./meshes/001_7.obj" scale="1 1 1"/>
        </geometry>
        <material name="mat_1"/>
    </visual>
    <collision>
        <origin rpy="0 0 0" xyz="0 0 0"/>
        <geometry>
        <mesh filename="./meshes/001_7.obj" scale="1 1 1"/>
        </geometry>
    </collision>
    </link>

    <joint name="joint_0" type="revolute" >
        <origin xyz="0 0 0.7" />
        <axis xyz="0 1 0" />
        <child link="link_1" />
        <parent link="link_0" />
        <limit lower="-0.872665" upper="0.872665" effort="10" velocity="3"/>
    </joint>

    <link name="link_1">
    <inertial>
        <origin rpy="0 0 0" xyz="0 0 0"/>
        <mass value="0.75"/>
        <inertia ixx="0.0005327014250829038" ixy="-8.910208422563106e-08" ixz="9.910415466524238e-09" iyy="0.0005015348207404789" iyz="1.228752069510437e-08" izz="0.0001362037121752979"/>
    </inertial>
    <visual>
        <origin rpy="0 0 0" xyz="0 0 0"/>
        <geometry>
        <mesh filename="./meshes/002_2.obj" scale="1 1 1"/>
        </geometry>
        <material name="mat_2"/>
    </visual>
    <collision>
        <origin rpy="0 0 0" xyz="0 0 0"/>
        <geometry>
        <mesh filename="./meshes/002_2.obj" scale="1 1 1"/>
        </geometry>
    </collision>
    </link>

    <joint name="joint_1" type="revolute" >
        <origin xyz="0 0 0.7" />
        <axis xyz="0 1 0" />
        <child link="link_2" />
        <parent link="link_1" />
        <limit lower="-0.872665" upper="0.872665" effort="10" velocity="3"/>
    </joint>

    <link name="link_2">
    <inertial>
        <origin rpy="0 0 0" xyz="0 0 0"/>
        <mass value="0.75"/>
        <inertia ixx="0.0004397613408125844" ixy="9.9295017092963e-08" ixz="-3.7141032753046395e-08" iyy="0.00044833212641787776" iyz="-1.206611973426756e-06" izz="7.890678398180441e-05"/>
    </inertial>
    <visual>
        <origin rpy="0 0 0" xyz="0 0 0"/>
        <geometry>
        <mesh filename="./meshes/003_1.obj" scale="1 1 1"/>
        </geometry>
        <material name="mat_3"/>
    </visual>
    <collision>
        <origin rpy="0 0 0" xyz="0 0 0"/>
        <geometry>
        <mesh filename="./meshes/003_1.obj" scale="1 1 1"/>
        </geometry>
    </collision>
    </link>

    <joint name="joint_base" type="fixed">
        <origin rpy="1.570796326794897 0 -1.570796326794897" xyz="1.05 0 0" />
        <child link="link_0" />
        <parent link="base" />
    </joint>
</robot>