
<?xml version='1.0' encoding='utf-8'?>
<robot name="partnet_d3add45f40a94ec680a3f97923d96d6e">
    <link name="base"><inertial><mass value="1.0" /><inertia ixx="1.0" ixy="0.0" ixz="0.0" iyy="1.0" iyz="0.0" izz="1.0" /></inertial></link>

    <material name="mat_1">
        <color rgba="0.468380722375921 0.7941437103296546 0.45007341531408185 1"/>
    </material>

    <material name="mat_2">
        <color rgba="0.22814780953405422 0.20459898630578588 0.87019014429948 1"/>
    </material>

    <material name="mat_3">
        <color rgba="0.7400439092343801 0.047850469946371654 0.8518838064074062 1"/>
    </material>

    <link name="link_0">
    <inertial>
        <origin rpy="0 0 0" xyz="0 0 0"/>
        <mass value="0.75"/>
        <inertia ixx="0.0003653626957916343" ixy="1.480439956073448e-11" ixz="1.297119649658398e-12" iyy="0.0003518469561397101" iyz="-2.5403399173485377e-11" izz="0.00014554671014186884"/>
    </inertial>
    <visual>
        <origin rpy="0 0 0" xyz="0 0 0"/>
        <geometry>
        <mesh filename="./meshes/cylinder_5.obj" scale="1 1 1"/>
        </geometry>
        <material name="mat_2"/>
    </visual>
    <collision>
        <origin rpy="0 0 0" xyz="0 0 0"/>
        <geometry>
        <mesh filename="./meshes/cylinder_5.obj" scale="1 1 1"/>
        </geometry>
    </collision>
    </link>

    <joint name="joint_0" type="revolute" >
        <origin xyz="0 0 0.4190413930772171" />
        <axis xyz="0 1 0" />
        <child link="link_1" />
        <parent link="link_0" />
        <limit lower="-1.57079632679" upper="1.57079632679" effort="10" velocity="3"/>
    </joint>

    <link name="link_1">
    <inertial>
        <origin rpy="0 0 0" xyz="0 0 0"/>
        <mass value="0.75"/>
        <inertia ixx="3.947909533449695e-05" ixy="-1.4190212301569757e-10" ixz="5.665240517860771e-09" iyy="3.9501552390052374e-05" iyz="1.5964273650764904e-09" izz="1.1729635046651036e-06"/>
    </inertial>
    <visual>
        <origin rpy="0 0 0" xyz="0 0 0"/>
        <geometry>
        <mesh filename="./meshes/tetrahedron_6.obj" scale="1 1 1"/>
        </geometry>
        <material name="mat_2"/>
    </visual>
    <collision>
        <origin rpy="0 0 0" xyz="0 0 0"/>
        <geometry>
        <mesh filename="./meshes/tetrahedron_6.obj" scale="1 1 1"/>
        </geometry>
    </collision>
    </link>

    <joint name="joint_1" type="revolute" >
        <origin xyz="0 0 0.8014854927721939" />
        <axis xyz="0 1 0" />
        <child link="link_2" />
        <parent link="link_1" />
        <limit lower="-1.57079632679" upper="1.57079632679" effort="10" velocity="3"/>
    </joint>

    <link name="link_2">
    <inertial>
        <origin rpy="0 0 0" xyz="0 0 0"/>
        <mass value="0.75"/>
        <inertia ixx="4.334647597307412e-05" ixy="5.209363225470901e-10" ixz="1.0714573601716547e-07" iyy="3.471707798956927e-05" iyz="-6.800154075681131e-08" izz="2.8929293817888477e-05"/>
    </inertial>
    <visual>
        <origin rpy="0 0 0" xyz="0 0 0"/>
        <geometry>
        <mesh filename="./meshes/pyramid_9.obj" scale="1 1 1"/>
        </geometry>
        <material name="mat_2"/>
    </visual>
    <collision>
        <origin rpy="0 0 0" xyz="0 0 0"/>
        <geometry>
        <mesh filename="./meshes/pyramid_9.obj" scale="1 1 1"/>
        </geometry>
    </collision>
    </link>

    <joint name="joint_base" type="fixed">
        <origin rpy="1.570796326794897 0 -1.570796326794897" xyz="1.5 0 0" />
        <child link="link_0" />
        <parent link="base" />
    </joint>
</robot>