
<?xml version='1.0' encoding='utf-8'?>
<robot name="partnet_d9528d3e008c432b8e2991e8daf1b2c9">
    <link name="base"><inertial><mass value="1.0" /><inertia ixx="1.0" ixy="0.0" ixz="0.0" iyy="1.0" iyz="0.0" izz="1.0" /></inertial></link>

    <material name="mat_1">
        <color rgba="0.035614530012785584 0.41601015472753655 0.865506396168503 1"/>
    </material>

    <material name="mat_2">
        <color rgba="0.9728952653714276 0.42314089865533067 0.9643235934517534 1"/>
    </material>

    <material name="mat_3">
        <color rgba="0.3045326541723372 0.9868991463254666 0.3159353364000209 1"/>
    </material>

    <link name="link_0">
    <inertial>
        <origin rpy="0 0 0" xyz="0 0 0"/>
        <mass value="0.75"/>
        <inertia ixx="0.00018312831741063539" ixy="1.1479306541181717e-12" ixz="1.8871130240271477e-13" iyy="0.00018453029984957315" iyz="-5.045386133744348e-12" izz="1.0894731853778701e-05"/>
    </inertial>
    <visual>
        <origin rpy="0 0 0" xyz="0 0 0"/>
        <geometry>
        <mesh filename="./meshes/cylinder_6.obj" scale="1 1 1"/>
        </geometry>
        <material name="mat_2"/>
    </visual>
    <collision>
        <origin rpy="0 0 0" xyz="0 0 0"/>
        <geometry>
        <mesh filename="./meshes/cylinder_6.obj" scale="1 1 1"/>
        </geometry>
    </collision>
    </link>

    <joint name="joint_0" type="revolute" >
        <origin xyz="0 0 0.5832563805306786" />
        <axis xyz="0 1 0" />
        <child link="link_1" />
        <parent link="link_0" />
        <limit lower="-1.57079632679" upper="1.57079632679" effort="10" velocity="3"/>
    </joint>

    <link name="link_1">
    <inertial>
        <origin rpy="0 0 0" xyz="0 0 0"/>
        <mass value="0.75"/>
        <inertia ixx="8.380739218668954e-06" ixy="-1.1271799807652954e-12" ixz="1.0365082337582467e-12" iyy="8.782028228398526e-06" iyz="8.562020416198533e-13" izz="4.401763325717547e-06"/>
    </inertial>
    <visual>
        <origin rpy="0 0 0" xyz="0 0 0"/>
        <geometry>
        <mesh filename="./meshes/diamond_4.obj" scale="1 1 1"/>
        </geometry>
        <material name="mat_3"/>
    </visual>
    <collision>
        <origin rpy="0 0 0" xyz="0 0 0"/>
        <geometry>
        <mesh filename="./meshes/diamond_4.obj" scale="1 1 1"/>
        </geometry>
    </collision>
    </link>

    <joint name="joint_1" type="revolute" >
        <origin xyz="0 0 0.338841083319736" />
        <axis xyz="0 1 0" />
        <child link="link_2" />
        <parent link="link_1" />
        <limit lower="-1.57079632679" upper="1.57079632679" effort="10" velocity="3"/>
    </joint>

    <link name="link_2">
    <inertial>
        <origin rpy="0 0 0" xyz="0 0 0"/>
        <mass value="0.75"/>
        <inertia ixx="0.0002190254509030383" ixy="-1.5995367077592857e-11" ixz="2.2524790159321923e-09" iyy="0.00022741744116478238" iyz="-1.3740421731493796e-10" izz="9.724466888361538e-06"/>
    </inertial>
    <visual>
        <origin rpy="0 0 0" xyz="0 0 0"/>
        <geometry>
        <mesh filename="./meshes/torus_6.obj" scale="1 1 1"/>
        </geometry>
        <material name="mat_2"/>
    </visual>
    <collision>
        <origin rpy="0 0 0" xyz="0 0 0"/>
        <geometry>
        <mesh filename="./meshes/torus_6.obj" scale="1 1 1"/>
        </geometry>
    </collision>
    </link>

    <joint name="joint_base" type="fixed">
        <origin rpy="1.570796326794897 0 -1.570796326794897" xyz="1.5 0 0" />
        <child link="link_0" />
        <parent link="base" />
    </joint>
</robot>